  File "/usr/local/lib/python3.11/site-packages/sqlalchemy/orm/attributes.py", line 453, in operate
    return op(self.comparator, *other, **kwargs)  # type: ignore[no-any-return]  # noqa: E501
           ^^^^^^^^^^^^^^^^^^^^^^^^^^^^^^^^^^^^^
  File "/usr/local/lib/python3.11/site-packages/sqlalchemy/sql/operators.py", line 584, in __eq__
    return self.operate(eq, other)
           ^^^^^^^^^^^^^^^^^^^^^^^
  File "/usr/local/lib/python3.11/site-packages/sqlalchemy/orm/properties.py", line 479, in operate
    return op(self.__clause_element__(), *other, **kwargs)  # type: ignore[no-any-return]  # noqa: E501
           ^^^^^^^^^^^^^^^^^^^^^^^^^^^^^^^^^^^^^^^^^^^^^^^
  File "/usr/local/lib/python3.11/site-packages/sqlalchemy/sql/annotation.py", line 371, in __eq__
    return self.__element.__class__.__eq__(self, other)
           ^^^^^^^^^^^^^^^^^^^^^^^^^^^^^^^^^^^^^^^^^^^^
  File "/usr/local/lib/python3.11/site-packages/sqlalchemy/sql/operators.py", line 584, in __eq__
    return self.operate(eq, other)
           ^^^^^^^^^^^^^^^^^^^^^^^
  File "/usr/local/lib/python3.11/site-packages/sqlalchemy/sql/elements.py", line 1523, in operate
    return op(self.comparator, *other, **kwargs)  # type: ignore[no-any-return]  # noqa: E501
           ^^^^^^^^^^^^^^^^^^^^^^^^^^^^^^^^^^^^^
  File "/usr/local/lib/python3.11/site-packages/sqlalchemy/sql/operators.py", line 584, in __eq__
    return self.operate(eq, other)
           ^^^^^^^^^^^^^^^^^^^^^^^
  File "/usr/local/lib/python3.11/site-packages/sqlalchemy/sql/type_api.py", line 212, in operate
    return op_fn(self.expr, op, *other, **addtl_kw)
           ^^^^^^^^^^^^^^^^^^^^^^^^^^^^^^^^^^^^^^^^
  File "/usr/local/lib/python3.11/site-packages/sqlalchemy/sql/default_comparator.py", line 121, in _boolean_compare
    obj = coercions.expect(
          ^^^^^^^^^^^^^^^^^
  File "/usr/local/lib/python3.11/site-packages/sqlalchemy/sql/coercions.py", line 395, in expect
    resolved = impl._literal_coercion(
               ^^^^^^^^^^^^^^^^^^^^^^^
  File "/usr/local/lib/python3.11/site-packages/sqlalchemy/sql/coercions.py", line 805, in _literal_coercion
    self._raise_for_expected(element, err=err)
  File "/usr/local/lib/python3.11/site-packages/sqlalchemy/sql/coercions.py", line 784, in _raise_for_expected
    return super()._raise_for_expected(
           ^^^^^^^^^^^^^^^^^^^^^^^^^^^^
  File "/usr/local/lib/python3.11/site-packages/sqlalchemy/sql/coercions.py", line 518, in _raise_for_expected
    raise exc.ArgumentError(msg, code=code) from err
sqlalchemy.exc.ArgumentError: SQL expression element or literal value expected, got <User id=406>.
INFO:     172.18.0.1:55722 - "POST /api/v1/points/history HTTP/1.1" 200 OK
INFO:     172.18.0.1:55718 - "POST /api/v1/points/referred_users HTTP/1.1" 200 OK
INFO:     172.18.0.1:55026 - "GET /api/v1/setup/status/setup_status/406 HTTP/1.1" 200 OK
INFO:     172.18.0.1:55026 - "GET /api/v1/setup/status/setup_status/406 HTTP/1.1" 200 OK
INFO:     172.18.0.1:56888 - "OPTIONS /api/v1/referral/get_code HTTP/1.1" 200 OK
INFO:     172.18.0.1:56892 - "OPTIONS /api/v1/referral/invitees HTTP/1.1" 200 OK
[DEBUG] Received cast_id: 406, type: <class 'int'>
[DEBUG] Using cast_id: 406
[ROUTER DEBUG] Returning result: {'cast_id': 406, 'status': 'pending', 'submitted_at': datetime.datetime(2025, 6, 14, 14, 30, 7), 'reviewed_at': None, 'rejection_reason': None, 'bank_name': None, 'branch_name': None, 'branch_code': None, 'account_type': None, 'account_number': None, 'account_holder': None, 'message': '本人確認申請を作成しました。後日結果を確認してください。'}
INFO:     172.18.0.1:56924 - "POST /api/v1/referral/get_code HTTP/1.1" 200 OK
INFO:     172.18.0.1:56890 - "GET /api/v1/cast/identity-verification/status HTTP/1.1" 200 OK
INFO:     172.18.0.1:56936 - "GET /api/v1/referral/invitees HTTP/1.1" 200 OK
[DEBUG] Received cast_id: 406, type: <class 'int'>
[DEBUG] Using cast_id: 406
[ROUTER DEBUG] Returning result: {'cast_id': 406, 'status': 'pending', 'submitted_at': datetime.datetime(2025, 6, 14, 14, 30, 7), 'reviewed_at': None, 'rejection_reason': None, 'bank_name': None, 'branch_name': None, 'branch_code': None, 'account_type': None, 'account_number': None, 'account_holder': None, 'message': '本人確認申請を作成しました。後日結果を確認してください。'}
INFO:     172.18.0.1:56924 - "GET /api/v1/cast/identity-verification/status HTTP/1.1" 200 OK
INFO:     172.18.0.1:56952 - "GET /api/v1/setup/status/setup_status/406 HTTP/1.1" 200 OK
[DEBUG] Received cast_id: 406, type: <class 'int'>
[DEBUG] Using cast_id: 406
[ROUTER DEBUG] Returning result: {'cast_id': 406, 'status': 'pending', 'submitted_at': datetime.datetime(2025, 6, 14, 14, 30, 7), 'reviewed_at': None, 'rejection_reason': None, 'bank_name': None, 'branch_name': None, 'branch_code': None, 'account_type': None, 'account_number': None, 'account_holder': None, 'message': '本人確認申請を作成しました。後日結果を確認してください。'}
INFO:     172.18.0.1:56960 - "GET /api/v1/cast/identity-verification/status HTTP/1.1" 200 OK
INFO:     172.18.0.1:56962 - "POST /api/v1/points/balance HTTP/1.1" 200 OK
INFO:     172.18.0.1:56966 - "POST /api/v1/user/profile HTTP/1.1" 500 Internal Server Error
ERROR:    Exception in ASGI application
Traceback (most recent call last):
  File "/usr/local/lib/python3.11/site-packages/sqlalchemy/sql/coercions.py", line 803, in _literal_coercion
    return expr._bind_param(operator, element, type_=bindparam_type)
           ^^^^^^^^^^^^^^^^^^^^^^^^^^^^^^^^^^^^^^^^^^^^^^^^^^^^^^^^^
  File "/usr/local/lib/python3.11/site-packages/sqlalchemy/sql/elements.py", line 4624, in _bind_param
    return BindParameter(
           ^^^^^^^^^^^^^^
  File "/usr/local/lib/python3.11/site-packages/sqlalchemy/sql/elements.py", line 2043, in __init__
    self.type = _compared_to_type.coerce_compared_value(
                ^^^^^^^^^^^^^^^^^^^^^^^^^^^^^^^^^^^^^^^^
  File "/usr/local/lib/python3.11/site-packages/sqlalchemy/sql/type_api.py", line 1059, in coerce_compared_value
    _coerced_type = _resolve_value_to_type(value)
                    ^^^^^^^^^^^^^^^^^^^^^^^^^^^^^
  File "/usr/local/lib/python3.11/site-packages/sqlalchemy/sql/sqltypes.py", line 3889, in _resolve_value_to_type
    raise exc.ArgumentError(
sqlalchemy.exc.ArgumentError: Object <User id=406> is not legal as a SQL literal value

The above exception was the direct cause of the following exception:

Traceback (most recent call last):
  File "/usr/local/lib/python3.11/site-packages/uvicorn/protocols/http/httptools_impl.py", line 401, in run_asgi
    result = await app(  # type: ignore[func-returns-value]
             ^^^^^^^^^^^^^^^^^^^^^^^^^^^^^^^^^^^^^^^^^^^^^^
  File "/usr/local/lib/python3.11/site-packages/uvicorn/middleware/proxy_headers.py", line 70, in __call__
    return await self.app(scope, receive, send)
           ^^^^^^^^^^^^^^^^^^^^^^^^^^^^^^^^^^^^
  File "/usr/local/lib/python3.11/site-packages/fastapi/applications.py", line 1054, in __call__
    await super().__call__(scope, receive, send)
  File "/usr/local/lib/python3.11/site-packages/starlette/applications.py", line 123, in __call__
    await self.middleware_stack(scope, receive, send)
  File "/usr/local/lib/python3.11/site-packages/starlette/middleware/errors.py", line 186, in __call__
    raise exc
  File "/usr/local/lib/python3.11/site-packages/starlette/middleware/errors.py", line 164, in __call__
    await self.app(scope, receive, _send)
  File "/usr/local/lib/python3.11/site-packages/starlette/middleware/cors.py", line 93, in __call__
    await self.simple_response(scope, receive, send, request_headers=headers)
  File "/usr/local/lib/python3.11/site-packages/starlette/middleware/cors.py", line 148, in simple_response
    await self.app(scope, receive, send)
  File "/usr/local/lib/python3.11/site-packages/starlette/middleware/base.py", line 189, in __call__
    with collapse_excgroups():
  File "/usr/local/lib/python3.11/contextlib.py", line 158, in __exit__
    self.gen.throw(typ, value, traceback)
  File "/usr/local/lib/python3.11/site-packages/starlette/_utils.py", line 93, in collapse_excgroups
    raise exc
  File "/usr/local/lib/python3.11/site-packages/starlette/middleware/base.py", line 191, in __call__
    response = await self.dispatch_func(request, call_next)
               ^^^^^^^^^^^^^^^^^^^^^^^^^^^^^^^^^^^^^^^^^^^^
  File "/app/app/main.py", line 100, in __call__
    return await call_next(request)
           ^^^^^^^^^^^^^^^^^^^^^^^^
  File "/usr/local/lib/python3.11/site-packages/starlette/middleware/base.py", line 165, in call_next
    raise app_exc
  File "/usr/local/lib/python3.11/site-packages/starlette/middleware/base.py", line 151, in coro
    await self.app(scope, receive_or_disconnect, send_no_error)
  File "/usr/local/lib/python3.11/site-packages/starlette/middleware/exceptions.py", line 65, in __call__
    await wrap_app_handling_exceptions(self.app, conn)(scope, receive, send)
  File "/usr/local/lib/python3.11/site-packages/starlette/_exception_handler.py", line 64, in wrapped_app
    raise exc
  File "/usr/local/lib/python3.11/site-packages/starlette/_exception_handler.py", line 53, in wrapped_app
    await app(scope, receive, sender)
  File "/usr/local/lib/python3.11/site-packages/starlette/routing.py", line 756, in __call__
    await self.middleware_stack(scope, receive, send)
  File "/usr/local/lib/python3.11/site-packages/starlette/routing.py", line 776, in app
    await route.handle(scope, receive, send)
  File "/usr/local/lib/python3.11/site-packages/starlette/routing.py", line 297, in handle
    await self.app(scope, receive, send)
  File "/usr/local/lib/python3.11/site-packages/starlette/routing.py", line 77, in app
    await wrap_app_handling_exceptions(app, request)(scope, receive, send)
  File "/usr/local/lib/python3.11/site-packages/starlette/_exception_handler.py", line 64, in wrapped_app
    raise exc
  File "/usr/local/lib/python3.11/site-packages/starlette/_exception_handler.py", line 53, in wrapped_app
    await app(scope, receive, sender)
  File "/usr/local/lib/python3.11/site-packages/starlette/routing.py", line 72, in app
    response = await func(request)
               ^^^^^^^^^^^^^^^^^^^
  File "/usr/local/lib/python3.11/site-packages/fastapi/routing.py", line 278, in app
    raw_response = await run_endpoint_function(
                   ^^^^^^^^^^^^^^^^^^^^^^^^^^^^
  File "/usr/local/lib/python3.11/site-packages/fastapi/routing.py", line 193, in run_endpoint_function
    return await run_in_threadpool(dependant.call, **values)
           ^^^^^^^^^^^^^^^^^^^^^^^^^^^^^^^^^^^^^^^^^^^^^^^^^
  File "/usr/local/lib/python3.11/site-packages/starlette/concurrency.py", line 42, in run_in_threadpool
    return await anyio.to_thread.run_sync(func, *args)
           ^^^^^^^^^^^^^^^^^^^^^^^^^^^^^^^^^^^^^^^^^^^
  File "/usr/local/lib/python3.11/site-packages/anyio/to_thread.py", line 56, in run_sync
    return await get_async_backend().run_sync_in_worker_thread(
           ^^^^^^^^^^^^^^^^^^^^^^^^^^^^^^^^^^^^^^^^^^^^^^^^^^^^
  File "/usr/local/lib/python3.11/site-packages/anyio/_backends/_asyncio.py", line 2470, in run_sync_in_worker_thread
    return await future
           ^^^^^^^^^^^^
  File "/usr/local/lib/python3.11/site-packages/anyio/_backends/_asyncio.py", line 967, in run
    result = context.run(func, *args)
             ^^^^^^^^^^^^^^^^^^^^^^^^
  File "/app/app/features/customer/user_profile/endpoints/user_profile.py", line 22, in fetch_user_profile
    return get_user_profile(current_user_id, db)
           ^^^^^^^^^^^^^^^^^^^^^^^^^^^^^^^^^^^^^
  File "/app/app/features/customer/user_profile/service/user_profile_service.py", line 11, in get_user_profile
    user = db.query(User).filter(User.id == user_id).first()
                                 ^^^^^^^^^^^^^^^^^^
  File "/usr/local/lib/python3.11/site-packages/sqlalchemy/sql/operators.py", line 584, in __eq__
    return self.operate(eq, other)
           ^^^^^^^^^^^^^^^^^^^^^^^
  File "/usr/local/lib/python3.11/site-packages/sqlalchemy/orm/attributes.py", line 453, in operate
    return op(self.comparator, *other, **kwargs)  # type: ignore[no-any-return]  # noqa: E501
           ^^^^^^^^^^^^^^^^^^^^^^^^^^^^^^^^^^^^^
  File "/usr/local/lib/python3.11/site-packages/sqlalchemy/sql/operators.py", line 584, in __eq__
    return self.operate(eq, other)
           ^^^^^^^^^^^^^^^^^^^^^^^
  File "/usr/local/lib/python3.11/site-packages/sqlalchemy/orm/properties.py", line 479, in operate
    return op(self.__clause_element__(), *other, **kwargs)  # type: ignore[no-any-return]  # noqa: E501
           ^^^^^^^^^^^^^^^^^^^^^^^^^^^^^^^^^^^^^^^^^^^^^^^
  File "/usr/local/lib/python3.11/site-packages/sqlalchemy/sql/annotation.py", line 371, in __eq__
    return self.__element.__class__.__eq__(self, other)
           ^^^^^^^^^^^^^^^^^^^^^^^^^^^^^^^^^^^^^^^^^^^^
  File "/usr/local/lib/python3.11/site-packages/sqlalchemy/sql/operators.py", line 584, in __eq__
    return self.operate(eq, other)
           ^^^^^^^^^^^^^^^^^^^^^^^
  File "/usr/local/lib/python3.11/site-packages/sqlalchemy/sql/elements.py", line 1523, in operate
    return op(self.comparator, *other, **kwargs)  # type: ignore[no-any-return]  # noqa: E501
           ^^^^^^^^^^^^^^^^^^^^^^^^^^^^^^^^^^^^^
  File "/usr/local/lib/python3.11/site-packages/sqlalchemy/sql/operators.py", line 584, in __eq__
    return self.operate(eq, other)
           ^^^^^^^^^^^^^^^^^^^^^^^
  File "/usr/local/lib/python3.11/site-packages/sqlalchemy/sql/type_api.py", line 212, in operate
    return op_fn(self.expr, op, *other, **addtl_kw)
           ^^^^^^^^^^^^^^^^^^^^^^^^^^^^^^^^^^^^^^^^
  File "/usr/local/lib/python3.11/site-packages/sqlalchemy/sql/default_comparator.py", line 121, in _boolean_compare
    obj = coercions.expect(
          ^^^^^^^^^^^^^^^^^
  File "/usr/local/lib/python3.11/site-packages/sqlalchemy/sql/coercions.py", line 395, in expect
    resolved = impl._literal_coercion(
               ^^^^^^^^^^^^^^^^^^^^^^^
  File "/usr/local/lib/python3.11/site-packages/sqlalchemy/sql/coercions.py", line 805, in _literal_coercion
    self._raise_for_expected(element, err=err)
  File "/usr/local/lib/python3.11/site-packages/sqlalchemy/sql/coercions.py", line 784, in _raise_for_expected
    return super()._raise_for_expected(
           ^^^^^^^^^^^^^^^^^^^^^^^^^^^^
  File "/usr/local/lib/python3.11/site-packages/sqlalchemy/sql/coercions.py", line 518, in _raise_for_expected
    raise exc.ArgumentError(msg, code=code) from err
sqlalchemy.exc.ArgumentError: SQL expression element or literal value expected, got <User id=406>.
INFO:     172.18.0.1:56980 - "POST /api/v1/points/referred_users HTTP/1.1" 200 OK
INFO:     172.18.0.1:56988 - "POST /api/v1/points/history HTTP/1.1" 200 OK
[DEBUG] Received cast_id: 406, type: <class 'int'>
[DEBUG] Using cast_id: 406
[ROUTER DEBUG] Returning result: {'cast_id': 406, 'status': 'pending', 'submitted_at': datetime.datetime(2025, 6, 14, 14, 30, 7), 'reviewed_at': None, 'rejection_reason': None, 'bank_name': None, 'branch_name': None, 'branch_code': None, 'account_type': None, 'account_number': None, 'account_holder': None, 'message': '本人確認申請を作成しました。後日結果を確認してください。'}
INFO:     172.18.0.1:56992 - "GET /api/v1/cast/identity-verification/status HTTP/1.1" 200 OK
INFO:     172.18.0.1:63788 - "GET /api/v1/setup/status/setup_status/406 HTTP/1.1" 200 OK
INFO:     172.18.0.1:63782 - "GET /api/v1/setup/status/setup_status/406 HTTP/1.1" 200 OK
INFO:     172.18.0.1:63802 - "POST /api/v1/points/history HTTP/1.1" 200 OK
INFO:     172.18.0.1:63896 - "GET /api/v1/setup/status/setup_status/406 HTTP/1.1" 200 OK
INFO:     172.18.0.1:63896 - "GET /api/v1/setup/status/setup_status/406 HTTP/1.1" 200 OK
[DEBUG] Received cast_id: 406, type: <class 'int'>
[DEBUG] Using cast_id: 406
[ROUTER DEBUG] Returning result: {'cast_id': 406, 'status': 'pending', 'submitted_at': datetime.datetime(2025, 6, 14, 14, 30, 7), 'reviewed_at': None, 'rejection_reason': None, 'bank_name': None, 'branch_name': None, 'branch_code': None, 'account_type': None, 'account_number': None, 'account_holder': None, 'message': '本人確認申請を作成しました。後日結果を確認してください。'}
INFO:     172.18.0.1:64340 - "GET /api/v1/cast/identity-verification/status HTTP/1.1" 200 OK
[DEBUG] Received cast_id: 406, type: <class 'int'>
[DEBUG] Using cast_id: 406
[ROUTER DEBUG] Returning result: {'cast_id': 406, 'status': 'pending', 'submitted_at': datetime.datetime(2025, 6, 14, 14, 30, 7), 'reviewed_at': None, 'rejection_reason': None, 'bank_name': None, 'branch_name': None, 'branch_code': None, 'account_type': None, 'account_number': None, 'account_holder': None, 'message': '本人確認申請を作成しました。後日結果を確認してください。'}
INFO:     172.18.0.1:64344 - "GET /api/v1/cast/identity-verification/status HTTP/1.1" 200 OK
INFO:     172.18.0.1:63896 - "GET /api/v1/setup/status/setup_status/406 HTTP/1.1" 200 OK
[DEBUG] Received cast_id: 406, type: <class 'int'>
[DEBUG] Using cast_id: 406
[ROUTER DEBUG] Returning result: {'cast_id': 406, 'status': 'pending', 'submitted_at': datetime.datetime(2025, 6, 14, 14, 30, 7), 'reviewed_at': None, 'rejection_reason': None, 'bank_name': None, 'branch_name': None, 'branch_code': None, 'account_type': None, 'account_number': None, 'account_holder': None, 'message': '本人確認申請を作成しました。後日結果を確認してください。'}
INFO:     172.18.0.1:64360 - "POST /api/v1/referral/get_code HTTP/1.1" 200 OK
INFO:     172.18.0.1:64356 - "GET /api/v1/referral/invitees HTTP/1.1" 200 OK
INFO:     172.18.0.1:64348 - "GET /api/v1/cast/identity-verification/status HTTP/1.1" 200 OK
[DEBUG] Received cast_id: 406, type: <class 'int'>
[DEBUG] Using cast_id: 406
[ROUTER DEBUG] Returning result: {'cast_id': 406, 'status': 'pending', 'submitted_at': datetime.datetime(2025, 6, 14, 14, 30, 7), 'reviewed_at': None, 'rejection_reason': None, 'bank_name': None, 'branch_name': None, 'branch_code': None, 'account_type': None, 'account_number': None, 'account_holder': None, 'message': '本人確認申請を作成しました。後日結果を確認してください。'}
INFO:     172.18.0.1:64356 - "GET /api/v1/cast/identity-verification/status HTTP/1.1" 200 OK
INFO:     172.18.0.1:64380 - "GET /api/v1/setup/status/setup_status/406 HTTP/1.1" 200 OK
INFO:app.features.cast.prof.service.prof_service:support_area値: None
INFO:app.features.cast.prof.service.prof_service:都道府県名取得開始: prefecture_ids=None
INFO:app.features.cast.prof.service.prof_service:都道府県IDが空のため、空リストを返します
INFO:app.features.cast.prof.service.prof_service:取得したsupport_area_names: []
INFO:app.features.cast.prof.service.prof_service:プロフィール取得: dispatch_prefecture=None
INFO:app.features.cast.prof.service.prof_service:--- 返却する profile_dict の内容 ---
INFO:app.features.cast.prof.service.prof_service:cast_id: 406 (Type: <class 'int'>)
INFO:app.features.cast.prof.service.prof_service:rank_id: 1 (Type: <class 'int'>)
INFO:app.features.cast.prof.service.prof_service:cast_type: B (Type: <class 'str'>)
INFO:app.features.cast.prof.service.prof_service:name: aaaa (Type: <class 'str'>)
INFO:app.features.cast.prof.service.prof_service:age: 20 (Type: <class 'int'>)
INFO:app.features.cast.prof.service.prof_service:height: 142 (Type: <class 'int'>)
INFO:app.features.cast.prof.service.prof_service:bust: None (Type: <class 'NoneType'>)
INFO:app.features.cast.prof.service.prof_service:cup: None (Type: <class 'NoneType'>)
INFO:app.features.cast.prof.service.prof_service:waist: None (Type: <class 'NoneType'>)
INFO:app.features.cast.prof.service.prof_service:hip: None (Type: <class 'NoneType'>)
INFO:app.features.cast.prof.service.prof_service:birthplace: None (Type: <class 'NoneType'>)
INFO:app.features.cast.prof.service.prof_service:blood_type: None (Type: <class 'NoneType'>)
INFO:app.features.cast.prof.service.prof_service:hobby: None (Type: <class 'NoneType'>)
INFO:app.features.cast.prof.service.prof_service:reservation_fee: None (Type: <class 'NoneType'>)
INFO:app.features.cast.prof.service.prof_service:reservation_fee_deli: None (Type: <class 'NoneType'>)
INFO:app.features.cast.prof.service.prof_service:self_introduction: None (Type: <class 'NoneType'>)
INFO:app.features.cast.prof.service.prof_service:job: None (Type: <class 'NoneType'>)
INFO:app.features.cast.prof.service.prof_service:dispatch_prefecture: None (Type: <class 'NoneType'>)
INFO:app.features.cast.prof.service.prof_service:support_area: None (Type: <class 'NoneType'>)
INFO:app.features.cast.prof.service.prof_service:popularity: 0 (Type: <class 'int'>)
INFO:app.features.cast.prof.service.prof_service:rating: 0.0 (Type: <class 'float'>)
INFO:app.features.cast.prof.service.prof_service:is_active: 0 (Type: <class 'int'>)
INFO:app.features.cast.prof.service.prof_service:available_at: None (Type: <class 'NoneType'>)
INFO:app.features.cast.prof.service.prof_service:created_at: None (Type: <class 'NoneType'>)
INFO:app.features.cast.prof.service.prof_service:updated_at: None (Type: <class 'NoneType'>)
INFO:app.features.cast.prof.service.prof_service:support_area_names: [] (Type: <class 'list'>)
INFO:app.features.cast.prof.service.prof_service:station_name: None (Type: <class 'NoneType'>)
INFO:app.features.cast.prof.service.prof_service:------------------------------------
INFO:app.features.cast.prof.service.prof_service:available_atがNoneだったので現在時刻に設定しました
INFO:app.features.cast.prof.service.prof_service:created_atがNoneだったので現在時刻に設定しました
[DEBUG] Received cast_id: 406, type: <class 'int'>
[DEBUG] Using cast_id: 406
[ROUTER DEBUG] Returning result: {'cast_id': 406, 'status': 'pending', 'submitted_at': datetime.datetime(2025, 6, 14, 14, 30, 7), 'reviewed_at': None, 'rejection_reason': None, 'bank_name': None, 'branch_name': None, 'branch_code': None, 'account_type': None, 'account_number': None, 'account_holder': None, 'message': '本人確認申請を作成しました。後日結果を確認してください。'}
INFO:     172.18.0.1:64392 - "GET /api/v1/cast/identity-verification/status HTTP/1.1" 200 OK
INFO:     172.18.0.1:64390 - "POST /api/v1/cast/prof/get HTTP/1.1" 200 OK
[DEBUG] Received cast_id: 406, type: <class 'int'>
[DEBUG] Using cast_id: 406
[ROUTER DEBUG] Returning result: {'cast_id': 406, 'status': 'pending', 'submitted_at': datetime.datetime(2025, 6, 14, 14, 30, 7), 'reviewed_at': None, 'rejection_reason': None, 'bank_name': None, 'branch_name': None, 'branch_code': None, 'account_type': None, 'account_number': None, 'account_holder': None, 'message': '本人確認申請を作成しました。後日結果を確認してください。'}
INFO:     172.18.0.1:64418 - "GET /api/v1/cast/identity-verification/status HTTP/1.1" 200 OK
[DEBUG] Received cast_id: 406, type: <class 'int'>
[DEBUG] Using cast_id: 406
[ROUTER DEBUG] Returning result: {'cast_id': 406, 'status': 'pending', 'submitted_at': datetime.datetime(2025, 6, 14, 14, 30, 7), 'reviewed_at': None, 'rejection_reason': None, 'bank_name': None, 'branch_name': None, 'branch_code': None, 'account_type': None, 'account_number': None, 'account_holder': None, 'message': '本人確認申請を作成しました。後日結果を確認してください。'}
INFO:     172.18.0.1:64390 - "GET /api/v1/cast/identity-verification/status HTTP/1.1" 200 OK
INFO:     172.18.0.1:60904 - "GET /api/v1/setup/status/setup_status/406 HTTP/1.1" 200 OK
INFO:     172.18.0.1:60904 - "GET /api/v1/setup/status/setup_status/406 HTTP/1.1" 200 OK
[DEBUG] Received cast_id: 406, type: <class 'int'>
[DEBUG] Using cast_id: 406
[ROUTER DEBUG] Returning result: {'cast_id': 406, 'status': 'pending', 'submitted_at': datetime.datetime(2025, 6, 14, 14, 30, 7), 'reviewed_at': None, 'rejection_reason': None, 'bank_name': None, 'branch_name': None, 'branch_code': None, 'account_type': None, 'account_number': None, 'account_holder': None, 'message': '本人確認申請を作成しました。後日結果を確認してください。'}
INFO:     172.18.0.1:60920 - "GET /api/v1/cast/identity-verification/status HTTP/1.1" 200 OK
[DEBUG] Received cast_id: 406, type: <class 'int'>
[DEBUG] Using cast_id: 406
[ROUTER DEBUG] Returning result: {'cast_id': 406, 'status': 'pending', 'submitted_at': datetime.datetime(2025, 6, 14, 14, 30, 7), 'reviewed_at': None, 'rejection_reason': None, 'bank_name': None, 'branch_name': None, 'branch_code': None, 'account_type': None, 'account_number': None, 'account_holder': None, 'message': '本人確認申請を作成しました。後日結果を確認してください。'}
INFO:     172.18.0.1:60924 - "GET /api/v1/cast/identity-verification/status HTTP/1.1" 200 OK
[DEBUG] Received cast_id: 406, type: <class 'int'>
[DEBUG] Using cast_id: 406
[ROUTER DEBUG] Returning result: {'cast_id': 406, 'status': 'pending', 'submitted_at': datetime.datetime(2025, 6, 14, 14, 30, 7), 'reviewed_at': None, 'rejection_reason': None, 'bank_name': None, 'branch_name': None, 'branch_code': None, 'account_type': None, 'account_number': None, 'account_holder': None, 'message': '本人確認申請を作成しました。後日結果を確認してください。'}
INFO:     172.18.0.1:60920 - "GET /api/v1/cast/identity-verification/status HTTP/1.1" 200 OK
[DEBUG] Received cast_id: 406, type: <class 'int'>
[DEBUG] Using cast_id: 406
[ROUTER DEBUG] Returning result: {'cast_id': 406, 'status': 'pending', 'submitted_at': datetime.datetime(2025, 6, 14, 14, 30, 7), 'reviewed_at': None, 'rejection_reason': None, 'bank_name': None, 'branch_name': None, 'branch_code': None, 'account_type': None, 'account_number': None, 'account_holder': None, 'message': '本人確認申請を作成しました。後日結果を確認してください。'}
INFO:     172.18.0.1:60924 - "GET /api/v1/cast/identity-verification/status HTTP/1.1" 200 OK
