INFO:     Will watch for changes in these directories: ['/app']
INFO:     Uvicorn running on http://0.0.0.0:8000 (Press CTRL+C to quit)
INFO:     Started reloader process [1] using WatchFiles
/usr/local/lib/python3.11/site-packages/pydantic/_internal/_config.py:373: UserWarning: Valid config keys have changed in V2:
* 'orm_mode' has been renamed to 'from_attributes'
  warnings.warn(message, UserWarning)
/usr/local/lib/python3.11/site-packages/pydantic/_internal/_config.py:373: UserWarning: Valid config keys have changed in V2:
* 'orm_mode' has been renamed to 'from_attributes'
  warnings.warn(message, UserWarning)
INFO:app.main:ローカル環境で動作中、デバッグログを有効にします
INFO:app.main:ローカル環境でCORS設定: ['https://cas.tokyo', 'https://cas.tokyo', 'http://localhost:3000', 'http://localhost:3001']
INFO:app.main:Application startup complete. Running in local environment.
INFO:     Started server process [11]
INFO:     Waiting for application startup.
INFO:     Application startup complete.
Models initialized
INFO:app.features.account.endpoints.auth_jwt:🚀 [refresh] トークン更新リクエスト受信
INFO:app.features.account.endpoints.auth_jwt:🔍 受信した refresh_token: eyJhbGciOiJIUzI1NiIsInR5cCI6IkpXVCJ9.eyJzdWIiOiI0MDYiLCJ1c2VyX2lkIjo0MDYsImV4cCI6MTc1OTgxNjQ5NiwiaWF0IjoxNzUyMDQwNDk2fQ.weRAX0w4MVH9iZE7SIzjtq_BcM7iDjtYcsX2_pwA_Sw
INFO:app.features.account.endpoints.auth_jwt:🔹 DBから取得した `user_type`: cast, `affi_type`: None
INFO:app.features.account.endpoints.auth_jwt:✅ 新しい認証トークンを発行: eyJhbGciOiJIUzI1NiIsInR5cCI6IkpXVCJ9.eyJzdWIiOiI0MDYiLCJ1c2VyX2lkIjo0MDYsInVzZXJfdHlwZSI6ImNhc3QiLCJhZmZpX3R5cGUiOm51bGwsImV4cCI6MTc1MjA2NzQwOCwiaWF0IjoxNzUyMDYwMjA4fQ.7VTE-ly9MAVpz2IyKbQ9_7zuDpX1n7vehLpmlFN72eU
INFO:     172.18.0.1:62508 - "POST /api/v1/account/auth/refresh HTTP/1.1" 200 OK
INFO:     172.18.0.1:62508 - "GET /api/v1/setup/status/setup_status/406 HTTP/1.1" 200 OK
INFO:     172.18.0.1:57798 - "GET /api/v1/setup/status/setup_status/406 HTTP/1.1" 200 OK
INFO:     172.18.0.1:56216 - "GET /api/v1/setup/status/setup_status/406 HTTP/1.1" 200 OK
INFO:     172.18.0.1:61588 - "GET /api/v1/setup/status/setup_status/406 HTTP/1.1" 200 OK
INFO:     172.18.0.1:57766 - "GET /api/v1/setup/status/setup_status/406 HTTP/1.1" 200 OK
INFO:     172.18.0.1:57754 - "GET /api/v1/setup/status/setup_status/406 HTTP/1.1" 200 OK
INFO:     172.18.0.1:60380 - "GET /api/v1/setup/status/setup_status/406 HTTP/1.1" 200 OK
INFO:     172.18.0.1:60558 - "GET /api/v1/setup/status/setup_status/406 HTTP/1.1" 200 OK
INFO:     172.18.0.1:62294 - "GET /api/v1/setup/status/setup_status/406 HTTP/1.1" 200 OK
INFO:     172.18.0.1:59632 - "GET /api/v1/setup/status/setup_status/406 HTTP/1.1" 200 OK
INFO:     172.18.0.1:61266 - "GET /api/v1/setup/status/setup_status/406 HTTP/1.1" 200 OK
INFO:     172.18.0.1:64312 - "GET /api/v1/setup/status/setup_status/406 HTTP/1.1" 200 OK
INFO:app.features.account.endpoints.auth_jwt:🚀 [refresh] トークン更新リクエスト受信
INFO:app.features.account.endpoints.auth_jwt:🔍 受信した refresh_token: eyJhbGciOiJIUzI1NiIsInR5cCI6IkpXVCJ9.eyJzdWIiOiI0MDYiLCJ1c2VyX2lkIjo0MDYsImV4cCI6MTc1OTgxNjQ5NiwiaWF0IjoxNzUyMDQwNDk2fQ.weRAX0w4MVH9iZE7SIzjtq_BcM7iDjtYcsX2_pwA_Sw
ERROR:app.features.account.endpoints.auth_jwt:⛔ リフレッシュトークンの検証エラー: (pymysql.err.OperationalError) (2013, 'Lost connection to MySQL server during query')
[SQL: SELECT users.id AS users_id, users.nick_name AS users_nick_name, users.prefectures AS users_prefectures, users.station AS users_station, users.line_id AS users_line_id, users.invitation_id AS users_invitation_id, users.tracking_id AS users_tracking_id, users.email AS users_email, users.email_verified AS users_email_verified, users.mobile_phone AS users_mobile_phone, users.phone_verification_code AS users_phone_verification_code, users.phone_verified AS users_phone_verified, users.picture_url AS users_picture_url, users.password_hash AS users_password_hash, users.sex AS users_sex, users.birth AS users_birth, users.user_type AS users_user_type, users.affi_type AS users_affi_type, users.last_login AS users_last_login, users.created_at AS users_created_at, users.updated_at AS users_updated_at, users.setup_status AS users_setup_status, users.stripe_customer_id AS users_stripe_customer_id 
FROM users 
WHERE users.id = %(id_1)s 
 LIMIT %(param_1)s]
[parameters: {'id_1': 406, 'param_1': 1}]
(Background on this error at: https://sqlalche.me/e/20/e3q8)
INFO:     172.18.0.1:56918 - "POST /api/v1/account/auth/refresh HTTP/1.1" 401 Unauthorized
INFO:app.features.account.endpoints.auth_jwt:🚀 [refresh] トークン更新リクエスト受信
INFO:app.features.account.endpoints.auth_jwt:🔍 受信した refresh_token: eyJhbGciOiJIUzI1NiIsInR5cCI6IkpXVCJ9.eyJzdWIiOiI0MDYiLCJ1c2VyX2lkIjo0MDYsImV4cCI6MTc1OTgxNjQ5NiwiaWF0IjoxNzUyMDQwNDk2fQ.weRAX0w4MVH9iZE7SIzjtq_BcM7iDjtYcsX2_pwA_Sw
INFO:app.features.account.endpoints.auth_jwt:🔹 DBから取得した `user_type`: cast, `affi_type`: None
INFO:app.features.account.endpoints.auth_jwt:✅ 新しい認証トークンを発行: eyJhbGciOiJIUzI1NiIsInR5cCI6IkpXVCJ9.eyJzdWIiOiI0MDYiLCJ1c2VyX2lkIjo0MDYsInVzZXJfdHlwZSI6ImNhc3QiLCJhZmZpX3R5cGUiOm51bGwsImV4cCI6MTc1MjExMDU2NCwiaWF0IjoxNzUyMTAzMzY0fQ.yOIRM3EUL1l8DZJyfwvWHxyIG0N5arlaK-0rIgU0l0g
INFO:     172.18.0.1:64878 - "POST /api/v1/account/auth/refresh HTTP/1.1" 200 OK
INFO:     172.18.0.1:64878 - "GET /api/v1/setup/status/setup_status/406 HTTP/1.1" 200 OK
INFO:     172.18.0.1:64890 - "OPTIONS /api/v1/account/auth/extend_refresh_token HTTP/1.1" 200 OK
🚀 【extend_refresh_token】 リクエストを今から受信
🚀 【extend_refresh_token】 リクエスト受信 - refresh_token: eyJhbGciOiJIUzI1NiIsInR5cCI6IkpXVCJ9.eyJzdWIiOiI0MDYiLCJ1c2VyX2lkIjo0MDYsImV4cCI6MTc1OTgxNjQ5NiwiaWF0IjoxNzUyMDQwNDk2fQ.weRAX0w4MVH9iZE7SIzjtq_BcM7iDjtYcsX2_pwA_Sw
🕒 【extend_refresh_token】 現在時刻: 1752103366 / refresh_token 有効期限: 1759816496 / 残り 7713130 秒
🔄 【extend_refresh_token】 `refresh_token` の期限が近いため更新: eyJhbGciOiJIUzI1NiIsInR5cCI6IkpXVCJ9.eyJzdWIiOiI0MDYiLCJ1c2VyX2lkIjo0MDYsImV4cCI6MTc1OTg3OTM2NiwiaWF0IjoxNzUyMTAzMzY2fQ.uyTqH0d48EfcFRFLAngLk5cj9yDQyAj_SJAqERBVcJo
INFO:     172.18.0.1:64898 - "POST /api/v1/account/auth/extend_refresh_token HTTP/1.1" 200 OK
INFO:     172.18.0.1:64904 - "OPTIONS /api/v1/account/auth/refresh HTTP/1.1" 200 OK
INFO:app.features.account.endpoints.auth_jwt:🚀 [refresh] トークン更新リクエスト受信
INFO:app.features.account.endpoints.auth_jwt:🔍 受信した refresh_token: eyJhbGciOiJIUzI1NiIsInR5cCI6IkpXVCJ9.eyJzdWIiOiI0MDYiLCJ1c2VyX2lkIjo0MDYsImV4cCI6MTc1OTg3OTM2NiwiaWF0IjoxNzUyMTAzMzY2fQ.uyTqH0d48EfcFRFLAngLk5cj9yDQyAj_SJAqERBVcJo
INFO:app.features.account.endpoints.auth_jwt:🔹 DBから取得した `user_type`: cast, `affi_type`: None
INFO:app.features.account.endpoints.auth_jwt:✅ 新しい認証トークンを発行: eyJhbGciOiJIUzI1NiIsInR5cCI6IkpXVCJ9.eyJzdWIiOiI0MDYiLCJ1c2VyX2lkIjo0MDYsInVzZXJfdHlwZSI6ImNhc3QiLCJhZmZpX3R5cGUiOm51bGwsImV4cCI6MTc1MjExMDU2NiwiaWF0IjoxNzUyMTAzMzY2fQ.MNGXw4rHf186NZ_fyYScZQoDVKuBLK24flzVH43X0-4
INFO:     172.18.0.1:64898 - "POST /api/v1/account/auth/refresh HTTP/1.1" 200 OK
INFO:     172.18.0.1:64904 - "OPTIONS /api/v1/cast/identity-verification/status HTTP/1.1" 200 OK
INFO:     172.18.0.1:64912 - "OPTIONS /api/v1/referral/get_code HTTP/1.1" 200 OK
INFO:     172.18.0.1:64924 - "OPTIONS /api/v1/referral/invitees HTTP/1.1" 200 OK
INFO:     172.18.0.1:64938 - "OPTIONS /api/v1/cast/identity-verification/status HTTP/1.1" 200 OK
INFO:     172.18.0.1:64898 - "GET /api/v1/cast/identity-verification/status HTTP/1.1" 401 Unauthorized
INFO:     172.18.0.1:64946 - "POST /api/v1/referral/get_code HTTP/1.1" 401 Unauthorized
INFO:     172.18.0.1:64960 - "GET /api/v1/referral/invitees HTTP/1.1" 401 Unauthorized
INFO:     172.18.0.1:64962 - "GET /api/v1/cast/identity-verification/status HTTP/1.1" 401 Unauthorized
INFO:     172.18.0.1:64878 - "GET /api/v1/setup/status/setup_status/406 HTTP/1.1" 200 OK
INFO:     172.18.0.1:64878 - "GET /api/v1/setup/status/setup_status/406 HTTP/1.1" 200 OK
INFO:     172.18.0.1:55900 - "GET /api/v1/setup/status/setup_status/406 HTTP/1.1" 200 OK
INFO:     172.18.0.1:55144 - "GET /api/v1/setup/status/setup_status/406 HTTP/1.1" 200 OK
INFO:     172.18.0.1:56640 - "GET /api/v1/account/line/login?tr=DEFAULT_ID HTTP/1.1" 200 OK
INFO:     172.18.0.1:56706 - "GET /api/v1/account/line/login?tr=DEFAULT_ID HTTP/1.1" 200 OK
INFO:     172.18.0.1:59094 - "GET /api/v1/account/line/login?tr=aB3x9Z HTTP/1.1" 200 OK
INFO:     172.18.0.1:56978 - "GET /api/v1/account/line/login?tr=aB3x9Z HTTP/1.1" 200 OK
INFO:     172.18.0.1:64422 - "GET /api/v1/account/line/login?tr=aB3x9Z HTTP/1.1" 200 OK
WARNING:  WatchFiles detected changes in 'app/features/account/endpoints/auth_line.py'. Reloading...
INFO:     Shutting down
INFO:     Waiting for application shutdown.
INFO:     Application shutdown complete.
INFO:     Finished server process [11]
WARNING:  WatchFiles detected changes in 'app/features/account/endpoints/auth_line.py'. Reloading...
/usr/local/lib/python3.11/site-packages/pydantic/_internal/_config.py:373: UserWarning: Valid config keys have changed in V2:
* 'orm_mode' has been renamed to 'from_attributes'
  warnings.warn(message, UserWarning)
/usr/local/lib/python3.11/site-packages/pydantic/_internal/_config.py:373: UserWarning: Valid config keys have changed in V2:
* 'orm_mode' has been renamed to 'from_attributes'
  warnings.warn(message, UserWarning)
INFO:app.main:ローカル環境で動作中、デバッグログを有効にします
INFO:app.main:ローカル環境でCORS設定: ['https://cas.tokyo', 'https://cas.tokyo', 'http://localhost:3000', 'http://localhost:3001']
INFO:app.main:Application startup complete. Running in local environment.
INFO:     Started server process [12099]
INFO:     Waiting for application startup.
INFO:     Application startup complete.
/usr/local/lib/python3.11/site-packages/pydantic/_internal/_config.py:373: UserWarning: Valid config keys have changed in V2:
* 'orm_mode' has been renamed to 'from_attributes'
  warnings.warn(message, UserWarning)
/usr/local/lib/python3.11/site-packages/pydantic/_internal/_config.py:373: UserWarning: Valid config keys have changed in V2:
* 'orm_mode' has been renamed to 'from_attributes'
  warnings.warn(message, UserWarning)
INFO:app.main:ローカル環境で動作中、デバッグログを有効にします
INFO:app.main:ローカル環境でCORS設定: ['https://cas.tokyo', 'https://cas.tokyo', 'http://localhost:3000', 'http://localhost:3001']
INFO:app.main:Application startup complete. Running in local environment.
INFO:     Started server process [12116]
INFO:     Waiting for application startup.
INFO:     Application startup complete.
Models initialized
INFO:app.features.account.endpoints.auth_line:📥 LINE認証リクエスト受信 - tr=aB3x9Z, tracking_id=None, actual=aB3x9Z
INFO:app.features.account.endpoints.auth_line:🔗 生成されたLINE認証URL: https://access.line.me/oauth2/v2.1/authorize?response_type=code&client_id=2005683762&redirect_uri=https%3A//api.cas.tokyo/api/v1/account/line/callback&state=tracking_id%3DaB3x9Z&scope=profile%20openid
INFO:app.features.account.endpoints.auth_line:🔗 stateパラメータ: 'tracking_id=aB3x9Z'
INFO:     172.18.0.1:64552 - "GET /api/v1/account/line/login?tr=aB3x9Z HTTP/1.1" 200 OK
WARNING:  WatchFiles detected changes in 'app/features/points/endpoints/admin_points.py'. Reloading...
INFO:     Shutting down
INFO:     Waiting for application shutdown.
INFO:     Application shutdown complete.
INFO:     Finished server process [12116]
WARNING:  WatchFiles detected changes in 'app/features/points/schemas/admin_points_schema.py'. Reloading...
/usr/local/lib/python3.11/site-packages/pydantic/_internal/_config.py:373: UserWarning: Valid config keys have changed in V2:
* 'orm_mode' has been renamed to 'from_attributes'
  warnings.warn(message, UserWarning)
/usr/local/lib/python3.11/site-packages/pydantic/_internal/_config.py:373: UserWarning: Valid config keys have changed in V2:
* 'orm_mode' has been renamed to 'from_attributes'
  warnings.warn(message, UserWarning)
INFO:app.main:ローカル環境で動作中、デバッグログを有効にします
INFO:app.main:ローカル環境でCORS設定: ['https://cas.tokyo', 'https://cas.tokyo', 'http://localhost:3000', 'http://localhost:3001']
INFO:app.main:Application startup complete. Running in local environment.
INFO:     Started server process [12448]
INFO:     Waiting for application startup.
INFO:     Application startup complete.
/usr/local/lib/python3.11/site-packages/pydantic/_internal/_config.py:373: UserWarning: Valid config keys have changed in V2:
* 'orm_mode' has been renamed to 'from_attributes'
  warnings.warn(message, UserWarning)
/usr/local/lib/python3.11/site-packages/pydantic/_internal/_config.py:373: UserWarning: Valid config keys have changed in V2:
* 'orm_mode' has been renamed to 'from_attributes'
  warnings.warn(message, UserWarning)
WARNING:  WatchFiles detected changes in 'app/features/points/repositories/points_repository.py'. Reloading...
INFO:app.main:ローカル環境で動作中、デバッグログを有効にします
INFO:app.main:ローカル環境でCORS設定: ['https://cas.tokyo', 'https://cas.tokyo', 'http://localhost:3000', 'http://localhost:3001']
INFO:app.main:Application startup complete. Running in local environment.
INFO:     Started server process [12464]
INFO:     Waiting for application startup.
INFO:     Application startup complete.
WARNING:  WatchFiles detected changes in 'app/features/points/endpoints/admin_points.py'. Reloading...
/usr/local/lib/python3.11/site-packages/pydantic/_internal/_config.py:373: UserWarning: Valid config keys have changed in V2:
* 'orm_mode' has been renamed to 'from_attributes'
  warnings.warn(message, UserWarning)
/usr/local/lib/python3.11/site-packages/pydantic/_internal/_config.py:373: UserWarning: Valid config keys have changed in V2:
* 'orm_mode' has been renamed to 'from_attributes'
  warnings.warn(message, UserWarning)
INFO:app.main:ローカル環境で動作中、デバッグログを有効にします
INFO:app.main:ローカル環境でCORS設定: ['https://cas.tokyo', 'https://cas.tokyo', 'http://localhost:3000', 'http://localhost:3001']
INFO:app.main:Application startup complete. Running in local environment.
INFO:     Started server process [12481]
INFO:     Waiting for application startup.
INFO:     Application startup complete.
WARNING:  WatchFiles detected changes in 'app/features/points/endpoints/admin_points.py'. Reloading...
WARNING:  WatchFiles detected changes in 'app/features/points/endpoints/admin_points.py'. Reloading...
/usr/local/lib/python3.11/site-packages/pydantic/_internal/_config.py:373: UserWarning: Valid config keys have changed in V2:
* 'orm_mode' has been renamed to 'from_attributes'
  warnings.warn(message, UserWarning)
/usr/local/lib/python3.11/site-packages/pydantic/_internal/_config.py:373: UserWarning: Valid config keys have changed in V2:
* 'orm_mode' has been renamed to 'from_attributes'
  warnings.warn(message, UserWarning)
INFO:app.main:ローカル環境で動作中、デバッグログを有効にします
INFO:app.main:ローカル環境でCORS設定: ['https://cas.tokyo', 'https://cas.tokyo', 'http://localhost:3000', 'http://localhost:3001']
INFO:app.main:Application startup complete. Running in local environment.
INFO:     Started server process [12494]
INFO:     Waiting for application startup.
INFO:     Application startup complete.
WARNING:  WatchFiles detected changes in 'app/features/points/endpoints/points_routers.py'. Reloading...
/usr/local/lib/python3.11/site-packages/pydantic/_internal/_config.py:373: UserWarning: Valid config keys have changed in V2:
* 'orm_mode' has been renamed to 'from_attributes'
  warnings.warn(message, UserWarning)
/usr/local/lib/python3.11/site-packages/pydantic/_internal/_config.py:373: UserWarning: Valid config keys have changed in V2:
* 'orm_mode' has been renamed to 'from_attributes'
  warnings.warn(message, UserWarning)
Process SpawnProcess-10:
Traceback (most recent call last):
  File "/usr/local/lib/python3.11/multiprocessing/process.py", line 314, in _bootstrap
    self.run()
  File "/usr/local/lib/python3.11/multiprocessing/process.py", line 108, in run
    self._target(*self._args, **self._kwargs)
  File "/usr/local/lib/python3.11/site-packages/uvicorn/_subprocess.py", line 80, in subprocess_started
    target(sockets=sockets)
  File "/usr/local/lib/python3.11/site-packages/uvicorn/server.py", line 65, in run
    return asyncio.run(self.serve(sockets=sockets))
           ^^^^^^^^^^^^^^^^^^^^^^^^^^^^^^^^^^^^^^^^
  File "/usr/local/lib/python3.11/asyncio/runners.py", line 190, in run
    return runner.run(main)
           ^^^^^^^^^^^^^^^^
  File "/usr/local/lib/python3.11/asyncio/runners.py", line 118, in run
    return self._loop.run_until_complete(task)
           ^^^^^^^^^^^^^^^^^^^^^^^^^^^^^^^^^^^
  File "uvloop/loop.pyx", line 1518, in uvloop.loop.Loop.run_until_complete
  File "/usr/local/lib/python3.11/site-packages/uvicorn/server.py", line 69, in serve
    await self._serve(sockets)
  File "/usr/local/lib/python3.11/site-packages/uvicorn/server.py", line 76, in _serve
    config.load()
  File "/usr/local/lib/python3.11/site-packages/uvicorn/config.py", line 434, in load
    self.loaded_app = import_from_string(self.app)
                      ^^^^^^^^^^^^^^^^^^^^^^^^^^^^
  File "/usr/local/lib/python3.11/site-packages/uvicorn/importer.py", line 22, in import_from_string
    raise exc from None
  File "/usr/local/lib/python3.11/site-packages/uvicorn/importer.py", line 19, in import_from_string
    module = importlib.import_module(module_str)
             ^^^^^^^^^^^^^^^^^^^^^^^^^^^^^^^^^^^
  File "/usr/local/lib/python3.11/importlib/__init__.py", line 126, in import_module
    return _bootstrap._gcd_import(name[level:], package, level)
           ^^^^^^^^^^^^^^^^^^^^^^^^^^^^^^^^^^^^^^^^^^^^^^^^^^^^
  File "<frozen importlib._bootstrap>", line 1204, in _gcd_import
  File "<frozen importlib._bootstrap>", line 1176, in _find_and_load
  File "<frozen importlib._bootstrap>", line 1147, in _find_and_load_unlocked
  File "<frozen importlib._bootstrap>", line 690, in _load_unlocked
  File "<frozen importlib._bootstrap_external>", line 940, in exec_module
  File "<frozen importlib._bootstrap>", line 241, in _call_with_frames_removed
  File "/app/app/main.py", line 2, in <module>
    from app.api.v1.routers.master_router import master_router  # 直接指定
    ^^^^^^^^^^^^^^^^^^^^^^^^^^^^^^^^^^^^^^^^^^^^^^^^^^^^^^^^^^
  File "/app/app/api/v1/routers/master_router.py", line 66, in <module>
    from app.features.points.endpoints.points_routers import points_routers
  File "/app/app/features/points/endpoints/points_routers.py", line 18, in <module>
    from app.features.points.endpoints.admin_points import router as admin_points_router
ModuleNotFoundError: No module named 'app.features.points.endpoints.admin_points'
Models initialized
INFO:     Stopping reloader process [1]
